<?xml version="1.0" encoding="utf-8"?>
<!-- =================================================================================== -->
<!-- |    This document was autogenerated by xacro from navvis_definition.xacro        | -->
<!-- |    EDITING THIS FILE BY HAND IS NOT RECOMMENDED                                 | -->
<!-- =================================================================================== -->
<robot name="navvis">
  <link name="base">
    <visual>
      <!-- Shift the box up half its height. !-->
      <origin rpy="0.0 0.0 0.0" xyz="0.0 0.0 0.96"/>
      <geometry>
        <box size="0.45 0.78 1.92"/>
      </geometry>
    </visual>
    <collision>
      <!-- Shift the box up half its height. !-->
      <origin rpy="0.0 0.0 0.0" xyz="0.0 0.0 0.96"/>
      <geometry>
        <box size="0.45 0.78 1.92"/>
      </geometry>
    </collision>
  </link>
  <link name="laser_vert_bottom">
    <visual>
      <geometry>
        <box size="0.0620 0.0620 0.0870"/>
      </geometry>
    </visual>
    <collision>
      <geometry>
        <box size="0.0620 0.0620 0.0870"/>
      </geometry>
    </collision>
  </link>
  <joint name="base_laser_vert_bottom_joint" type="fixed">
    <parent link="base"/>
    <child link="laser_vert_bottom"/>
    <origin rpy="3.1355 -1.3045 0.0025" xyz="0.3158 -0.0021 0.5100"/>
  </joint>
  <link name="laser_vert_top_right">
    <visual>
      <geometry>
        <box size="0.0620 0.0620 0.0870"/>
      </geometry>
    </visual>
    <collision>
      <geometry>
        <box size="0.0620 0.0620 0.0870"/>
      </geometry>
    </collision>
  </link>
  <joint name="base_laser_vert_top_right_joint" type="fixed">
    <parent link="base"/>
    <child link="laser_vert_top_right"/>
    <origin rpy="-1.1760 0.6313 -1.9377" xyz="0.2978 -0.1450 1.8451"/>
  </joint>
  <link name="laser_vert_top_left">
    <visual>
      <geometry>
        <box size="0.0620 0.0620 0.0870"/>
      </geometry>
    </visual>
    <collision>
      <geometry>
        <box size="0.0620 0.0620 0.0870"/>
      </geometry>
    </collision>
  </link>
  <joint name="base_laser_vert_top_left_joint" type="fixed">
    <parent link="base"/>
    <child link="laser_vert_top_left"/>
    <origin rpy="1.1780 0.6198 1.9560" xyz="0.2997 0.1531 1.8443"/>
  </joint>
  <link name="laser_vert_horiz">
    <visual>
      <geometry>
        <cylinder length="0.0720" radius="0.0520"/>
      </geometry>
    </visual>
    <collision>
      <geometry>
        <cylinder length="0.0720" radius="0.0520"/>
      </geometry>
    </collision>
  </link>
  <joint name="base_laser_vert_horiz_joint" type="fixed">
    <parent link="base"/>
    <child link="laser_vert_horiz"/>
    <origin rpy="-0.0012 0.1146 -0.0015" xyz="0.2325 0.0001 1.9201"/>
  </joint>
  <link name="wheel_left">
    <visual>
      <geometry>
        <cylinder length="0.0500" radius="0.2000"/>
      </geometry>
    </visual>
    <collision>
      <geometry>
        <cylinder length="0.0500" radius="0.2000"/>
      </geometry>
    </collision>
  </link>
  <joint name="base_wheel_left_joint" type="continuous">
    <parent link="base"/>
    <child link="wheel_left"/>
    <origin rpy="-1.57079632679 0.0000 0.0000" xyz="-0.1000 0.4 0.0000"/>
    <axis xyz="0.0000 0.0000 1.0000"/>
    <limit effort="30" velocity="30"/>
  </joint>
  <link name="wheel_right">
    <visual>
      <geometry>
        <cylinder length="0.0500" radius="0.2000"/>
      </geometry>
    </visual>
    <collision>
      <geometry>
        <cylinder length="0.0500" radius="0.2000"/>
      </geometry>
    </collision>
  </link>
  <joint name="base_wheel_right_joint" type="continuous">
    <parent link="base"/>
    <child link="wheel_right"/>
    <origin rpy="-1.57079632679 0.0000 0.0000" xyz="-0.1000 -0.4 0.0000"/>
    <axis xyz="0.0000 0.0000 1.0000"/>
    <limit effort="30" velocity="30"/>
  </joint>
  <link name="wheel_center">
    <visual>
      <geometry>
        <cylinder length="0.0500" radius="0.1500"/>
      </geometry>
    </visual>
    <collision>
      <geometry>
        <cylinder length="0.0500" radius="0.1500"/>
      </geometry>
    </collision>
  </link>
  <joint name="base_wheel_center_joint" type="continuous">
    <parent link="base"/>
    <child link="wheel_center"/>
    <origin rpy="-1.57079632679 0.0000 0.0000" xyz="0.1000 0.0000 -0.0500"/>
    <axis xyz="0.0000 0.0000 1.0000"/>
    <limit effort="30" velocity="30"/>
  </joint>
</robot>

